[2022-12-04 16:33:54,107] {taskinstance.py:1032} INFO - Dependencies all met for <TaskInstance: data_ingest_yuda.local_to_gcs_task manual__2022-12-04T16:23:53.008846+00:00 [queued]>
[2022-12-04 16:33:54,115] {taskinstance.py:1032} INFO - Dependencies all met for <TaskInstance: data_ingest_yuda.local_to_gcs_task manual__2022-12-04T16:23:53.008846+00:00 [queued]>
[2022-12-04 16:33:54,116] {taskinstance.py:1238} INFO - 
--------------------------------------------------------------------------------
[2022-12-04 16:33:54,116] {taskinstance.py:1239} INFO - Starting attempt 2 of 2
[2022-12-04 16:33:54,117] {taskinstance.py:1240} INFO - 
--------------------------------------------------------------------------------
[2022-12-04 16:33:54,127] {taskinstance.py:1259} INFO - Executing <Task(PythonOperator): local_to_gcs_task> on 2022-12-04 16:23:53.008846+00:00
[2022-12-04 16:33:54,131] {standard_task_runner.py:52} INFO - Started process 1549 to run task
[2022-12-04 16:33:54,134] {standard_task_runner.py:76} INFO - Running: ['***', 'tasks', 'run', 'data_ingest_yuda', 'local_to_gcs_task', 'manual__2022-12-04T16:23:53.008846+00:00', '--job-id', '12', '--raw', '--subdir', 'DAGS_FOLDER/data_ingest_yuda.py', '--cfg-path', '/tmp/tmpzmeu04m4', '--error-file', '/tmp/tmpnr1i17mw']
[2022-12-04 16:33:54,135] {standard_task_runner.py:77} INFO - Job 12: Subtask local_to_gcs_task
[2022-12-04 16:33:54,179] {logging_mixin.py:109} INFO - Running <TaskInstance: data_ingest_yuda.local_to_gcs_task manual__2022-12-04T16:23:53.008846+00:00 [running]> on host 73a87de6132e
[2022-12-04 16:33:54,220] {taskinstance.py:1426} INFO - Exporting the following env vars:
AIRFLOW_CTX_DAG_OWNER=yudasatrias
AIRFLOW_CTX_DAG_ID=data_ingest_yuda
AIRFLOW_CTX_TASK_ID=local_to_gcs_task
AIRFLOW_CTX_EXECUTION_DATE=2022-12-04T16:23:53.008846+00:00
AIRFLOW_CTX_DAG_RUN_ID=manual__2022-12-04T16:23:53.008846+00:00
[2022-12-04 16:33:54,221] {logging_mixin.py:109} INFO - INI CLIENT:
[2022-12-04 16:33:54,223] {taskinstance.py:1700} ERROR - Task failed with exception
Traceback (most recent call last):
  File "/home/airflow/.local/lib/python3.7/site-packages/airflow/models/taskinstance.py", line 1329, in _run_raw_task
    self._execute_task_with_callbacks(context)
  File "/home/airflow/.local/lib/python3.7/site-packages/airflow/models/taskinstance.py", line 1455, in _execute_task_with_callbacks
    result = self._execute_task(context, self.task)
  File "/home/airflow/.local/lib/python3.7/site-packages/airflow/models/taskinstance.py", line 1511, in _execute_task
    result = execute_callable(context=context)
  File "/home/airflow/.local/lib/python3.7/site-packages/airflow/operators/python.py", line 174, in execute
    return_value = self.execute_callable()
  File "/home/airflow/.local/lib/python3.7/site-packages/airflow/operators/python.py", line 185, in execute_callable
    return self.python_callable(*self.op_args, **self.op_kwargs)
  File "/opt/airflow/dags/data_ingest_yuda.py", line 76, in upload_to_gcs
    client = storage.Client()
  File "/home/airflow/.local/lib/python3.7/site-packages/google/cloud/storage/client.py", line 128, in __init__
    _http=_http,
  File "/home/airflow/.local/lib/python3.7/site-packages/google/cloud/client.py", line 318, in __init__
    _ClientProjectMixin.__init__(self, project=project, credentials=credentials)
  File "/home/airflow/.local/lib/python3.7/site-packages/google/cloud/client.py", line 266, in __init__
    project = self._determine_default(project)
  File "/home/airflow/.local/lib/python3.7/site-packages/google/cloud/client.py", line 285, in _determine_default
    return _determine_default_project(project)
  File "/home/airflow/.local/lib/python3.7/site-packages/google/cloud/_helpers.py", line 186, in _determine_default_project
    _, project = google.auth.default()
  File "/home/airflow/.local/lib/python3.7/site-packages/google/auth/_default.py", line 459, in default
    credentials, project_id = checker()
  File "/home/airflow/.local/lib/python3.7/site-packages/google/auth/_default.py", line 222, in _get_explicit_environ_credentials
    os.environ[environment_vars.CREDENTIALS]
  File "/home/airflow/.local/lib/python3.7/site-packages/google/auth/_default.py", line 108, in load_credentials_from_file
    "File {} was not found.".format(filename)
google.auth.exceptions.DefaultCredentialsError: File /.google/credentials/google_credentials.json was not found.
[2022-12-04 16:33:54,238] {taskinstance.py:1277} INFO - Marking task as FAILED. dag_id=data_ingest_yuda, task_id=local_to_gcs_task, execution_date=20221204T162353, start_date=20221204T163354, end_date=20221204T163354
[2022-12-04 16:33:54,249] {standard_task_runner.py:92} ERROR - Failed to execute job 12 for task local_to_gcs_task
Traceback (most recent call last):
  File "/home/airflow/.local/lib/python3.7/site-packages/airflow/task/task_runner/standard_task_runner.py", line 85, in _start_by_fork
    args.func(args, dag=self.dag)
  File "/home/airflow/.local/lib/python3.7/site-packages/airflow/cli/cli_parser.py", line 48, in command
    return func(*args, **kwargs)
  File "/home/airflow/.local/lib/python3.7/site-packages/airflow/utils/cli.py", line 92, in wrapper
    return f(*args, **kwargs)
  File "/home/airflow/.local/lib/python3.7/site-packages/airflow/cli/commands/task_command.py", line 298, in task_run
    _run_task_by_selected_method(args, dag, ti)
  File "/home/airflow/.local/lib/python3.7/site-packages/airflow/cli/commands/task_command.py", line 107, in _run_task_by_selected_method
    _run_raw_task(args, ti)
  File "/home/airflow/.local/lib/python3.7/site-packages/airflow/cli/commands/task_command.py", line 184, in _run_raw_task
    error_file=args.error_file,
  File "/home/airflow/.local/lib/python3.7/site-packages/airflow/utils/session.py", line 70, in wrapper
    return func(*args, session=session, **kwargs)
  File "/home/airflow/.local/lib/python3.7/site-packages/airflow/models/taskinstance.py", line 1329, in _run_raw_task
    self._execute_task_with_callbacks(context)
  File "/home/airflow/.local/lib/python3.7/site-packages/airflow/models/taskinstance.py", line 1455, in _execute_task_with_callbacks
    result = self._execute_task(context, self.task)
  File "/home/airflow/.local/lib/python3.7/site-packages/airflow/models/taskinstance.py", line 1511, in _execute_task
    result = execute_callable(context=context)
  File "/home/airflow/.local/lib/python3.7/site-packages/airflow/operators/python.py", line 174, in execute
    return_value = self.execute_callable()
  File "/home/airflow/.local/lib/python3.7/site-packages/airflow/operators/python.py", line 185, in execute_callable
    return self.python_callable(*self.op_args, **self.op_kwargs)
  File "/opt/airflow/dags/data_ingest_yuda.py", line 76, in upload_to_gcs
    client = storage.Client()
  File "/home/airflow/.local/lib/python3.7/site-packages/google/cloud/storage/client.py", line 128, in __init__
    _http=_http,
  File "/home/airflow/.local/lib/python3.7/site-packages/google/cloud/client.py", line 318, in __init__
    _ClientProjectMixin.__init__(self, project=project, credentials=credentials)
  File "/home/airflow/.local/lib/python3.7/site-packages/google/cloud/client.py", line 266, in __init__
    project = self._determine_default(project)
  File "/home/airflow/.local/lib/python3.7/site-packages/google/cloud/client.py", line 285, in _determine_default
    return _determine_default_project(project)
  File "/home/airflow/.local/lib/python3.7/site-packages/google/cloud/_helpers.py", line 186, in _determine_default_project
    _, project = google.auth.default()
  File "/home/airflow/.local/lib/python3.7/site-packages/google/auth/_default.py", line 459, in default
    credentials, project_id = checker()
  File "/home/airflow/.local/lib/python3.7/site-packages/google/auth/_default.py", line 222, in _get_explicit_environ_credentials
    os.environ[environment_vars.CREDENTIALS]
  File "/home/airflow/.local/lib/python3.7/site-packages/google/auth/_default.py", line 108, in load_credentials_from_file
    "File {} was not found.".format(filename)
google.auth.exceptions.DefaultCredentialsError: File /.google/credentials/google_credentials.json was not found.
[2022-12-04 16:33:54,266] {local_task_job.py:154} INFO - Task exited with return code 1
[2022-12-04 16:33:54,297] {local_task_job.py:264} INFO - 0 downstream tasks scheduled from follow-on schedule check
